Workbook

Sheet Модель
A1: Информационная модель «Личные силовые тренировки»
A3: Цель модели
A4: Отслеживать нагрузку и прогресс в силовых тренировках: считать объём работы, видеть рост рабочих весов, замечать недогруженные группы мышц и прогнозировать, когда будет достигнута силовая цель.
A6: Вопросы, на которые отвечает модель
A7: 1. Какой объём работы (тоннаж) выполнен за тренировку, неделю, весь цикл?
A8: 2. Как растут рабочие веса и расчётный одноповторный максимум (1ПМ)?
A9: 3. Какие группы мышц недогружены, а какие перегружены относительно нормы?
A10: 4. Через сколько недель при текущем темпе будет достигнута цель в приседе?
A12: Тип модели: знаковая, табличная (реляционная) — таблицы «Упражнения» и «Тренировки», связанные по коду упражнения, плюс расчётный лист «Итоги» и диаграмма динамики.
A14: Существенные свойства системы
A15: Учитываются: упражнение (группа мышц, снаряд, тип, участвует ли собственный вес), дата занятия, вес отягощения, число подходов и повторов.
A16: Не учитываются как несущественные для цели: темп выполнения, время отдыха между подходами, пульс, самочувствие, питание, марка снаряда.
... A23: Параметры модели (жёлтые ячейки можно менять — это «эксперимент» с моделью)
A24: Собственный вес спортсмена, кг | B24: 72
A25: Шаг прибавки рабочего веса за неделю, кг | B25: 2.5
A26: Цель: рабочий вес в приседаниях, кг | B26: 100
A27: Норма рабочих подходов на группу мышц в неделю | B27: 10
A28: Дата начала цикла | B28: 46244
A29: Расчётная («сегодняшняя») дата | B29: 46285
A31: Легенда: синий шрифт — исходные данные, вводимые вручную; чёрный — значения, вычисляемые формулами. Данные тренировочного дневника за цикл 10.08–18.09.2026.

Sheet Упражнения
A1: Код | B1: Упражнение | C1: Группа мышц | D1: Снаряд | E1: Тип | F1: Учитывать собственный вес
A2: E01 | B2: Приседания со штангой | C2: Ноги | D2: Штанга | E2: базовое | F2: нет
A3: E02 | B3: Жим штанги лёжа | C3: Грудь | D3: Штанга | E3: базовое | F3: нет
A4: E03 | B4: Становая тяга | C4: Спина | D4: Штанга | E4: базовое | F4: нет
A5: E04 | B5: Тяга штанги в наклоне | C5: Спина | D5: Штанга | E5: базовое | F5: нет
A6: E05 | B6: Жим гантелей сидя | C6: Плечи | D6: Гантели | E6: базовое | F6: нет
A7: E06 | B7: Подтягивания | C7: Спина | D7: Своё тело | E7: базовое | F7: да
A8: E07 | B8: Отжимания на брусьях | C8: Грудь | D8: Своё тело | E8: базовое | F8: да
A9: E08 | B9: Подъём штанги на бицепс | C9: Руки | D9: Штанга | E9: изолирующее | F9: нет
A10: E09 | B10: Французский жим | C10: Руки | D10: Штанга | E10: изолирующее | F10: нет
A11: E10 | B11: Разгибание ног в тренажёре | C11: Ноги | D11: Тренажёр | E11: изолирующее | F11: нет
A12: E11 | B12: Жим ногами | C12: Ноги | D12: Тренажёр | E12: базовое | F12: нет
A13: E12 | B13: Скручивания на пресс | C13: Пресс | D13: Своё тело | E13: изолирующее | F13: нет

Sheet Тренировки
A1: № | B1: Дата | C1: Код упр. | D1: Упражнение (авто) | E1: Группа мышц (авто) | F1: Вес отягощения, кг | G1: Подходы | H1: Повторы | I1: Тоннаж, кг (авто) | J1: 1ПМ по Эпли, кг (авто) | K1: Неделя (авто) | L1: Новая тренировка (авто)
A2: 1 | B2: 46244 | C2: E01 | D2: =IFERROR(INDEX(Упражнения!$B$2:$B$13,MATCH($C2,Упражнения!$A$2:$A$13,0)),"нет такого упражнения") | E2: =IFERROR(INDEX(Упражнения!$C$2:$C$13,MATCH($C2,Упражнения!$A$2:$A$13,0)),"") | F2: 60 | G2: 5 | H2: 5 | I2: =($F2+IF(INDEX(Упражнения!$F$2:$F$13,MATCH($C2,Упражнения!$A$2:$A$13,0))="да",Модель!$B$24,0))*$G2*$H2 | J2: =ROUND(($F2+IF(INDEX(Упражнения!$F$2:$F$13,MATCH($C2,Упражнения!$A$2:$A$13,0))="да",Модель!$B$24,0))*(1+$H2/30),1) | K2: =INT(($B2-Модель!$B$28)/7)+1 | L2: =IF(COUNTIF($B$2:$B2,$B2)=1,1,0)
A3: 2 | B3: 46244 | C3: E02 | D3: =IFERROR(INDEX(Упражнения!$B$2:$B$13,MATCH($C3,Упражнения!$A$2:$A$13,0)),"нет такого упражнения") | E3: =IFERROR(INDEX(Упражнения!$C$2:$C$13,MATCH($C3,Упражнения!$A$2:$A$13,0)),"") | F3: 45 | G3: 5 | H3: 5 | I3: =($F3+IF(INDEX(Упражнения!$F$2:$F$13,MATCH($C3,Упражнения!$A$2:$A$13,0))="да",Модель!$B$24,0))*$G3*$H3 | J3: =ROUND(($F3+IF(INDEX(Упражнения!$F$2:$F$13,MATCH($C3,Упражнения!$A$2:$A$13,0))="да",Модель!$B$24,0))*(1+$H3/30),1) | K3: =INT(($B3-Модель!$B$28)/7)+1 | L3: =IF(COUNTIF($B$2:$B3,$B3)=1,1,0)
A4: 3 | B4: 46244 | C4: E08 | D4: =IFERROR(INDEX(Упражнения!$B$2:$B$13,MATCH($C4,Упражнения!$A$2:$A$13,0)),"нет такого упражнения") | E4: =IFERROR(INDEX(Упражнения!$C$2:$C$13,MATCH($C4,Упражнения!$A$2:$A$13,0)),"") | F4: 25 | G4: 3 | H4: 10 | I4: =($F4+IF(INDEX(Упражнения!$F$2:$F$13,MATCH($C4,Упражнения!$A$2:$A$13,0))="да",Модель!$B$24,0))*$G4*$H4 | J4: =ROUND(($F4+IF(INDEX(Упражнения!$F$2:$F$13,MATCH($C4,Упражнения!$A$2:$A$13,0))="да",Модель!$B$24,0))*(1+$H4/30),1) | K4: =INT(($B4-Модель!$B$28)/7)+1 | L4: =IF(COUNTIF($B$2:$B4,$B4)=1,1,0)
A5: 4 | B5: 46244 | C5: E12 | D5: =IFERROR(INDEX(Упражнения!$B$2:$B$13,MATCH($C5,Упражнения!$A$2:$A$13,0)),"нет такого упражнения") | E5: =IFERROR(INDEX(Упражнения!$C$2:$C$13,MATCH($C5,Упражнения!$A$2:$A$13,0)),"") | F5: 0 | G5: 3 | H5: 20 | I5: =($F5+IF(INDEX(Упражнения!$F$2:$F$13,MATCH($C5,Упражнения!$A$2:$A$13,0))="да",Модель!$B$24,0))*$G5*$H5 | J5: =ROUND(($F5+IF(INDEX(Упражнения!$F$2:$F$13,MATCH($C5,Упражнения!$A$2:$A$13,0))="да",Модель!$B$24,0))*(1+$H5/30),1) | K5: =INT(($B5-Модель!$B$28)/7)+1 | L5: =IF(COUNTIF($B$2:$B5,$B5)=1,1,0)
A6: 5 | B6: 46246 | C6: E03 | D6: =IFERROR(INDEX(Упражнения!$B$2:$B$13,MATCH($C6,Упражнения!$A$2:$A$13,0)),"нет такого упражнения") | E6: =IFERROR(INDEX(Упражнения!$C$2:$C$13,MATCH($C6,Упражнения!$A$2:$A$13,0)),"") | F6: 70 | G6: 5 | H6: 5 | I6: =($F6+IF(INDEX(Упражнения!$F$2:$F$13,MATCH($C6,Упражнения!$A$2:$A$13,0))="да",Модель!$B$24,0))*$G6*$H6 | J6: =ROUND(($F6+IF(INDEX(Упражнения!$F$2:$F$13,MATCH($C6,Упражнения!$A$2:$A$13,0))="да",Модель!$B$24,0))*(1+$H6/30),1) | K6: =INT(($B6-Модель!$B$28)/7)+1 | L6: =IF(COUNTIF($B$2:$B6,$B6)=1,1,0)
A7: 6 | B7: 46246 | C7: E04 | D7: =IFERROR(INDEX(Упражнения!$B$2:$B$13,MATCH($C7,Упражнения!$A$2:$A$13,0)),"нет такого упражнения") | E7: =IFERROR(INDEX(Упражнения!$C$2:$C$13,MATCH($C7,Упражнения!$A$2:$A$13,0)),"") | F7: 40 | G7: 4 | H7: 8 | I7: =($F7+IF(INDEX(Упражнения!$F$2:$F$13,MATCH($C7,Упражнения!$A$2:$A$13,0))="да",Модель!$B$24,0))*$G7*$H7 | J7: =ROUND(($F7+IF(INDEX(Упражнения!$F$2:$F$13,MATCH($C7,Упражнения!$A$2:$A$13,0))="да",Модель!$B$24,0))*(1+$H7/30),1) | K7: =INT(($B7-Модель!$B$28)/7)+1 | L7: =IF(COUNTIF($B$2:$B7,$B7)=1,1,0)
A8: 7 | B8: 46246 | C8: E06 | D8: =IFERROR(INDEX(Упражнения!$B$2:$B$13,MATCH($C8,Упражнения!$A$2:$A$13,0)),"нет такого упражнения") | E8: =IFERROR(INDEX(Упражнения!$C$2:$C$13,MATCH($C8,Упражнения!$A$2:$A$13,0)),"") | F8: 0 | G8: 4 | H8: 8 | I8: =($F8+IF(INDEX(Упражнения!$F$2:$F$13,MATCH($C8,Упражнения!$A$2:$A$13,0))="да",Модель!$B$24,0))*$G8*$H8 | J8: =ROUND(($F8+IF(INDEX(Упражнения!$F$2:$F$13,MATCH($C8,Упражнения!$A$2:$A$13,0))="да",Модель!$B$24,0))*(1+$H8/30),1) | K8: =INT(($B8-Модель!$B$28)/7)+1 | L8: =IF(COUNTIF($B$2:$B8,$B8)=1,1,0)
A9: 8 | B9: 46246 | C9: E09 | D9: =IFERROR(INDEX(Упражнения!$B$2:$B$13,MATCH($C9,Упражнения!$A$2:$A$13,0)),"нет такого упражнения") | E9: =IFERROR(INDEX(Упражнения!$C$2:$C$13,MATCH($C9,Упражнения!$A$2:$A$13,0)),"") | F9: 22.5 | G9: 3 | H9: 10 | I9: =($F9+IF(INDEX(Упражнения!$F$2:$F$13,MATCH($C9,Упражнения!$A$2:$A$13,0))="да",Модель!$B$24,0))*$G9*$H9 | J9: =ROUND(($F9+IF(INDEX(Упражнения!$F$2:$F$13,MATCH($C9,Упражнения!$A$2:$A$13,0))="да",Модель!$B$24,0))*(1+$H9/30),1) | K9: =INT(($B9-Модель!$B$28)/7)+1 | L9: =IF(COUNTIF($B$2:$B9,$B9)=1,1,0)
A10: 9 | B10: 46248 | C10: E11 | D10: =IFERROR(INDEX(Упражнения!$B$2:$B$13,MATCH($C10,Упражнения!$A$2:$A$13,0)),"нет такого упражнения") | E10: =IFERROR(INDEX(Упражнения!$C$2:$C$13,MATCH($C10,Упражнения!$A$2:$A$13,0)),"") | F10: 120 | G10: 4 | H10: 10 | I10: =($F10+IF(INDEX(Упражнения!$F$2:$F$13,MATCH($C10,Упражнения!$A$2:$A$13,0))="да",Модель!$B$24,0))*$G10*$H10 | J10: =ROUND(($F10+IF(INDEX(Упражнения!$F$2:$F$13,MATCH($C10,Упражнения!$A$2:$A$13,0))="да",Модель!$B$24,0))*(1+$H10/30),1) | K10: =INT(($B10-Модель!$B$28)/7)+1 | L10: =IF(COUNTIF($B$2:$B10,$B10)=1,1,0)
A11: 10 | B11: 46248 | C11: E05 | D11: =IFERROR(INDEX(Упражнения!$B$2:$B$13,MATCH($C11,Упражнения!$A$2:$A$13,0)),"нет такого упражнения") | E11: =IFERROR(INDEX(Упражнения!$C$2:$C$13,MATCH($C11,Упражнения!$A$2:$A$13,0)),"") | F11: 32 | G11: 4 | H11: 10 | I11: =($F11+IF(INDEX(Упражнения!$F$2:$F$13,MATCH($C11,Упражнения!$A$2:$A$13,0))="да",Модель!$B$24,0))*$G11*$H11 | J11: =ROUND(($F11+IF(INDEX(Упражнения!$F$2:$F$13,MATCH($C11,Упражнения!$A$2:$A$13,0))="да",Модель!$B$24,0))*(1+$H11/30),1) | K11: =INT(($B11-Модель!$B$28)/7)+1 | L11: =IF(COUNTIF($B$2:$B11,$B11)=1,1,0)
A12: 11 | B12: 46248 | C12: E07 | D12: =IFERROR(INDEX(Упражнения!$B$2:$B$13,MATCH($C12,Упражнения!$A$2:$A$13,0)),"нет такого упражнения") | E12: =IFERROR(INDEX(Упражнения!$C$2:$C$13,MATCH($C12,Упражнения!$A$2:$A$13,0)),"") | F12: 0 | G12: 3 | H12: 10 | I12: =($F12+IF(INDEX(Упражнения!$F$2:$F$13,MATCH($C12,Упражнения!$A$2:$A$13,0))="да",Модель!$B$24,0))*$G12*$H12 | J12: =ROUND(($F12+IF(INDEX(Упражнения!$F$2:$F$13,MATCH($C12,Упражнения!$A$2:$A$13,0))="да",Модель!$B$24,0))*(1+$H12/30),1) | K12: =INT(($B12-Модель!$B$28)/7)+1 | L12: =IF(COUNTIF($B$2:$B12,$B12)=1,1,0)
A13: 12 | B13: 46248 | C13: E10 | D13: =IFERROR(INDEX(Упражнения!$B$2:$B$13,MATCH($C13,Упражнения!$A$2:$A$13,0)),"нет такого упражнения") | E13: =IFERROR(INDEX(Упражнения!$C$2:$C$13,MATCH($C13,Упражнения!$A$2:$A$13,0)),"") | F13: 30 | G13: 3 | H13: 12 | I13: =($F13+IF(INDEX(Упражнения!$F$2:$F$13,MATCH($C13,Упражнения!$A$2:$A$13,0))="да",Модель!$B$24,0))*$G13*$H13 | J13: =ROUND(($F13+IF(INDEX(Упражнения!$F$2:$F$13,MATCH($C13,Упражнения!$A$2:$A$13,0))="да",Модель!$B$24,0))*(1+$H13/30),1) | K13: =INT(($B13-Модель!$B$28)/7)+1 | L13: =IF(COUNTIF($B$2:$B13,$B13)=1,1,0)
... A73: 72 | B73: 46283 | C73: E10 | D73: =IFERROR(INDEX(Упражнения!$B$2:$B$13,MATCH($C73,Упражнения!$A$2:$A$13,0)),"нет такого упражнения") | E73: =IFERROR(INDEX(Упражнения!$C$2:$C$13,MATCH($C73,Упражнения!$A$2:$A$13,0)),"") | F73: 42.5 | G73: 3 | H73: 12 | I73: =($F73+IF(INDEX(Упражнения!$F$2:$F$13,MATCH($C73,Упражнения!$A$2:$A$13,0))="да",Модель!$B$24,0))*$G73*$H73 | J73: =ROUND(($F73+IF(INDEX(Упражнения!$F$2:$F$13,MATCH($C73,Упражнения!$A$2:$A$13,0))="да",Модель!$B$24,0))*(1+$H73/30),1) | K73: =INT(($B73-Модель!$B$28)/7)+1 | L73: =IF(COUNTIF($B$2:$B73,$B73)=1,1,0)

Sheet Итоги
A1: Результаты моделирования
A3: Общие показатели цикла
A4: Тренировок проведено | B4: =SUM(Тренировки!$L$2:$L$73)
A5: Записей (упражнений выполнено) | B5: =COUNTA(Тренировки!$C$2:$C$73)
A6: Недель в цикле | B6: =MAX(Тренировки!$K$2:$K$73)
A7: Общий тоннаж, кг | B7: =SUM(Тренировки!$I$2:$I$73)
A8: Средний тоннаж за тренировку, кг | B8: =IFERROR(ROUND(SUM(Тренировки!$I$2:$I$73)/SUM(Тренировки!$L$2:$L$73),0),0)
A9: Всего рабочих подходов | B9: =SUM(Тренировки!$G$2:$G$73)
A10: Подходов за тренировку (среднее) | B10: =IFERROR(ROUND(SUM(Тренировки!$G$2:$G$73)/SUM(Тренировки!$L$2:$L$73),1),0)
A11: Дней с последней тренировки | B11: =Модель!$B$29-MAX(Тренировки!$B$2:$B$73)
A13: Нагрузка по группам мышц
A14: Группа мышц | B14: Подходов всего | C14: Подходов в неделю | D14: Тоннаж, кг | E14: Оценка нагрузки
A15: Ноги | B15: =SUMIF(Тренировки!$E$2:$E$73,$A15,Тренировки!$G$2:$G$73) | C15: =IFERROR(ROUND($B15/MAX(Тренировки!$K$2:$K$73),1),0) | D15: =SUMIF(Тренировки!$E$2:$E$73,$A15,Тренировки!$I$2:$I$73) | E15: =IF($C15<Модель!$B$27*0.8,"мало",IF($C15>Модель!$B$27*1.2,"много","норма"))
A16: Грудь | B16: =SUMIF(Тренировки!$E$2:$E$73,$A16,Тренировки!$G$2:$G$73) | C16: =IFERROR(ROUND($B16/MAX(Тренировки!$K$2:$K$73),1),0) | D16: =SUMIF(Тренировки!$E$2:$E$73,$A16,Тренировки!$I$2:$I$73) | E16: =IF($C16<Модель!$B$27*0.8,"мало",IF($C16>Модель!$B$27*1.2,"много","норма"))
A17: Спина | B17: =SUMIF(Тренировки!$E$2:$E$73,$A17,Тренировки!$G$2:$G$73) | C17: =IFERROR(ROUND($B17/MAX(Тренировки!$K$2:$K$73),1),0) | D17: =SUMIF(Тренировки!$E$2:$E$73,$A17,Тренировки!$I$2:$I$73) | E17: =IF($C17<Модель!$B$27*0.8,"мало",IF($C17>Модель!$B$27*1.2,"много","норма"))
A18: Плечи | B18: =SUMIF(Тренировки!$E$2:$E$73,$A18,Тренировки!$G$2:$G$73) | C18: =IFERROR(ROUND($B18/MAX(Тренировки!$K$2:$K$73),1),0) | D18: =SUMIF(Тренировки!$E$2:$E$73,$A18,Тренировки!$I$2:$I$73) | E18: =IF($C18<Модель!$B$27*0.8,"мало",IF($C18>Модель!$B$27*1.2,"много","норма"))
A19: Руки | B19: =SUMIF(Тренировки!$E$2:$E$73,$A19,Тренировки!$G$2:$G$73) | C19: =IFERROR(ROUND($B19/MAX(Тренировки!$K$2:$K$73),1),0) | D19: =SUMIF(Тренировки!$E$2:$E$73,$A19,Тренировки!$I$2:$I$73) | E19: =IF($C19<Модель!$B$27*0.8,"мало",IF($C19>Модель!$B$27*1.2,"много","норма"))
A20: Пресс | B20: =SUMIF(Тренировки!$E$2:$E$73,$A20,Тренировки!$G$2:$G$73) | C20: =IFERROR(ROUND($B20/MAX(Тренировки!$K$2:$K$73),1),0) | D20: =SUMIF(Тренировки!$E$2:$E$73,$A20,Тренировки!$I$2:$I$73) | E20: =IF($C20<Модель!$B$27*0.8,"мало",IF($C20>Модель!$B$27*1.2,"много","норма"))
A22: Динамика по неделям
A23: Неделя | B23: Тренировок | C23: Тоннаж, кг | D23: Подходов | E23: Рабочий вес в приседе, кг
A24: 1 | B24: =SUMIF(Тренировки!$K$2:$K$73,$A24,Тренировки!$L$2:$L$73) | C24: =SUMIF(Тренировки!$K$2:$K$73,$A24,Тренировки!$I$2:$I$73) | D24: =SUMIF(Тренировки!$K$2:$K$73,$A24,Тренировки!$G$2:$G$73) | E24: =IFERROR(SUMIFS(Тренировки!$F$2:$F$73,Тренировки!$C$2:$C$73,"E01",Тренировки!$K$2:$K$73,$A24)/COUNTIFS(Тренировки!$C$2:$C$73,"E01",Тренировки!$K$2:$K$73,$A24),0)
A25: 2 | B25: =SUMIF(Тренировки!$K$2:$K$73,$A25,Тренировки!$L$2:$L$73) | C25: =SUMIF(Тренировки!$K$2:$K$73,$A25,Тренировки!$I$2:$I$73) | D25: =SUMIF(Тренировки!$K$2:$K$73,$A25,Тренировки!$G$2:$G$73) | E25: =IFERROR(SUMIFS(Тренировки!$F$2:$F$73,Тренировки!$C$2:$C$73,"E01",Тренировки!$K$2:$K$73,$A25)/COUNTIFS(Тренировки!$C$2:$C$73,"E01",Тренировки!$K$2:$K$73,$A25),0)
A26: 3 | B26: =SUMIF(Тренировки!$K$2:$K$73,$A26,Тренировки!$L$2:$L$73) | C26: =SUMIF(Тренировки!$K$2:$K$73,$A26,Тренировки!$I$2:$I$73) | D26: =SUMIF(Тренировки!$K$2:$K$73,$A26,Тренировки!$G$2:$G$73) | E26: =IFERROR(SUMIFS(Тренировки!$F$2:$F$73,Тренировки!$C$2:$C$73,"E01",Тренировки!$K$2:$K$73,$A26)/COUNTIFS(Тренировки!$C$2:$C$73,"E01",Тренировки!$K$2:$K$73,$A26),0)
A27: 4 | B27: =SUMIF(Тренировки!$K$2:$K$73,$A27,Тренировки!$L$2:$L$73) | C27: =SUMIF(Тренировки!$K$2:$K$73,$A27,Тренировки!$I$2:$I$73) | D27: =SUMIF(Тренировки!$K$2:$K$73,$A27,Тренировки!$G$2:$G$73) | E27: =IFERROR(SUMIFS(Тренировки!$F$2:$F$73,Тренировки!$C$2:$C$73,"E01",Тренировки!$K$2:$K$73,$A27)/COUNTIFS(Тренировки!$C$2:$C$73,"E01",Тренировки!$K$2:$K$73,$A27),0)
A28: 5 | B28: =SUMIF(Тренировки!$K$2:$K$73,$A28,Тренировки!$L$2:$L$73) | C28: =SUMIF(Тренировки!$K$2:$K$73,$A28,Тренировки!$I$2:$I$73) | D28: =SUMIF(Тренировки!$K$2:$K$73,$A28,Тренировки!$G$2:$G$73) | E28: =IFERROR(SUMIFS(Тренировки!$F$2:$F$73,Тренировки!$C$2:$C$73,"E01",Тренировки!$K$2:$K$73,$A28)/COUNTIFS(Тренировки!$C$2:$C$73,"E01",Тренировки!$K$2:$K$73,$A28),0)
A29: 6 | B29: =SUMIF(Тренировки!$K$2:$K$73,$A29,Тренировки!$L$2:$L$73) | C29: =SUMIF(Тренировки!$K$2:$K$73,$A29,Тренировки!$I$2:$I$73) | D29: =SUMIF(Тренировки!$K$2:$K$73,$A29,Тренировки!$G$2:$G$73) | E29: =IFERROR(SUMIFS(Тренировки!$F$2:$F$73,Тренировки!$C$2:$C$73,"E01",Тренировки!$K$2:$K$73,$A29)/COUNTIFS(Тренировки!$C$2:$C$73,"E01",Тренировки!$K$2:$K$73,$A29),0)
A31: Прогресс по базовым упражнениям
A32: Код | B32: Упражнение | C32: Вес в 1-ю неделю, кг | D32: Вес в последнюю неделю, кг | E32: Прирост, кг | F32: Прирост, % | G32: Максимальный 1ПМ, кг
A33: E01 | B33: =IFERROR(INDEX(Упражнения!$B$2:$B$13,MATCH($A33,Упражнения!$A$2:$A$13,0)),"") | C33: =IFERROR(SUMIFS(Тренировки!$F$2:$F$73,Тренировки!$C$2:$C$73,$A33,Тренировки!$K$2:$K$73,1)/COUNTIFS(Тренировки!$C$2:$C$73,$A33,Тренировки!$K$2:$K$73,1),0) | D33: =IFERROR(SUMIFS(Тренировки!$F$2:$F$73,Тренировки!$C$2:$C$73,$A33,Тренировки!$K$2:$K$73,MAX(Тренировки!$K$2:$K$73))/COUNTIFS(Тренировки!$C$2:$C$73,$A33,Тренировки!$K$2:$K$73,MAX(Тренировки!$K$2:$K$73)),0) | E33: =$D33-$C33 | F33: =IFERROR($E33/$C33,0) | G33: =IFERROR(SUMPRODUCT(MAX((Тренировки!$C$2:$C$73=$A33)*Тренировки!$J$2:$J$73)),0)
A34: E02 | B34: =IFERROR(INDEX(Упражнения!$B$2:$B$13,MATCH($A34,Упражнения!$A$2:$A$13,0)),"") | C34: =IFERROR(SUMIFS(Тренировки!$F$2:$F$73,Тренировки!$C$2:$C$73,$A34,Тренировки!$K$2:$K$73,1)/COUNTIFS(Тренировки!$C$2:$C$73,$A34,Тренировки!$K$2:$K$73,1),0) | D34: =IFERROR(SUMIFS(Тренировки!$F$2:$F$73,Тренировки!$C$2:$C$73,$A34,Тренировки!$K$2:$K$73,MAX(Тренировки!$K$2:$K$73))/COUNTIFS(Тренировки!$C$2:$C$73,$A34,Тренировки!$K$2:$K$73,MAX(Тренировки!$K$2:$K$73)),0) | E34: =$D34-$C34 | F34: =IFERROR($E34/$C34,0) | G34: =IFERROR(SUMPRODUCT(MAX((Тренировки!$C$2:$C$73=$A34)*Тренировки!$J$2:$J$73)),0)
A35: E03 | B35: =IFERROR(INDEX(Упражнения!$B$2:$B$13,MATCH($A35,Упражнения!$A$2:$A$13,0)),"") | C35: =IFERROR(SUMIFS(Тренировки!$F$2:$F$73,Тренировки!$C$2:$C$73,$A35,Тренировки!$K$2:$K$73,1)/COUNTIFS(Тренировки!$C$2:$C$73,$A35,Тренировки!$K$2:$K$73,1),0) | D35: =IFERROR(SUMIFS(Тренировки!$F$2:$F$73,Тренировки!$C$2:$C$73,$A35,Тренировки!$K$2:$K$73,MAX(Тренировки!$K$2:$K$73))/COUNTIFS(Тренировки!$C$2:$C$73,$A35,Тренировки!$K$2:$K$73,MAX(Тренировки!$K$2:$K$73)),0) | E35: =$D35-$C35 | F35: =IFERROR($E35/$C35,0) | G35: =IFERROR(SUMPRODUCT(MAX((Тренировки!$C$2:$C$73=$A35)*Тренировки!$J$2:$J$73)),0)
A36: E04 | B36: =IFERROR(INDEX(Упражнения!$B$2:$B$13,MATCH($A36,Упражнения!$A$2:$A$13,0)),"") | C36: =IFERROR(SUMIFS(Тренировки!$F$2:$F$73,Тренировки!$C$2:$C$73,$A36,Тренировки!$K$2:$K$73,1)/COUNTIFS(Тренировки!$C$2:$C$73,$A36,Тренировки!$K$2:$K$73,1),0) | D36: =IFERROR(SUMIFS(Тренировки!$F$2:$F$73,Тренировки!$C$2:$C$73,$A36,Тренировки!$K$2:$K$73,MAX(Тренировки!$K$2:$K$73))/COUNTIFS(Тренировки!$C$2:$C$73,$A36,Тренировки!$K$2:$K$73,MAX(Тренировки!$K$2:$K$73)),0) | E36: =$D36-$C36 | F36: =IFERROR($E36/$C36,0) | G36: =IFERROR(SUMPRODUCT(MAX((Тренировки!$C$2:$C$73=$A36)*Тренировки!$J$2:$J$73)),0)
A37: E05 | B37: =IFERROR(INDEX(Упражнения!$B$2:$B$13,MATCH($A37,Упражнения!$A$2:$A$13,0)),"") | C37: =IFERROR(SUMIFS(Тренировки!$F$2:$F$73,Тренировки!$C$2:$C$73,$A37,Тренировки!$K$2:$K$73,1)/COUNTIFS(Тренировки!$C$2:$C$73,$A37,Тренировки!$K$2:$K$73,1),0) | D37: =IFERROR(SUMIFS(Тренировки!$F$2:$F$73,Тренировки!$C$2:$C$73,$A37,Тренировки!$K$2:$K$73,MAX(Тренировки!$K$2:$K$73))/COUNTIFS(Тренировки!$C$2:$C$73,$A37,Тренировки!$K$2:$K$73,MAX(Тренировки!$K$2:$K$73)),0) | E37: =$D37-$C37 | F37: =IFERROR($E37/$C37,0) | G37: =IFERROR(SUMPRODUCT(MAX((Тренировки!$C$2:$C$73=$A37)*Тренировки!$J$2:$J$73)),0)
A38: E11 | B38: =IFERROR(INDEX(Упражнения!$B$2:$B$13,MATCH($A38,Упражнения!$A$2:$A$13,0)),"") | C38: =IFERROR(SUMIFS(Тренировки!$F$2:$F$73,Тренировки!$C$2:$C$73,$A38,Тренировки!$K$2:$K$73,1)/COUNTIFS(Тренировки!$C$2:$C$73,$A38,Тренировки!$K$2:$K$73,1),0) | D38: =IFERROR(SUMIFS(Тренировки!$F$2:$F$73,Тренировки!$C$2:$C$73,$A38,Тренировки!$K$2:$K$73,MAX(Тренировки!$K$2:$K$73))/COUNTIFS(Тренировки!$C$2:$C$73,$A38,Тренировки!$K$2:$K$73,MAX(Тренировки!$K$2:$K$73)),0) | E38: =$D38-$C38 | F38: =IFERROR($E38/$C38,0) | G38: =IFERROR(SUMPRODUCT(MAX((Тренировки!$C$2:$C$73=$A38)*Тренировки!$J$2:$J$73)),0)
A40: Прогноз достижения цели (приседания со штангой)
A41: Текущий рабочий вес, кг | B41: =IFERROR(SUMIFS(Тренировки!$F$2:$F$73,Тренировки!$C$2:$C$73,"E01",Тренировки!$K$2:$K$73,MAX(Тренировки!$K$2:$K$73))/COUNTIFS(Тренировки!$C$2:$C$73,"E01",Тренировки!$K$2:$K$73,MAX(Тренировки!$K$2:$K$73)),0)
A42: Цель, кг | B42: =Модель!$B$26
A43: Осталось набрать, кг | B43: =MAX(0,$B42-$B41)
A44: Недель при текущем шаге | B44: =IFERROR(ROUNDUP($B43/Модель!$B$25,0),0)
A45: Ожидаемая дата достижения цели | B45: =Модель!$B$29+$B44*7
...
